Workbook

Sheet Catálogo
A1: id | B1: titulo | C1: titulo_es | D1: tema | E1: ambiente | F1: descripcion_optimizada | G1: descripcion_es | H1: titulo_miniatura | I1: hashtags | J1: etiquetas | K1: imagen_miniatura | L1: url_video | M1: raiz_hz | N1: modo | O1: registro | P1: semilla | Q1: tono | R1: duracion_min | S1: pantalla_oscura_min | T1: comando_regeneracion | U1: comando_ambiente | V1: estado | W1: fecha_publicacion | X1: vistas | Y1: suscriptores | Z1: subs_por_1000
A2: OBRA-001 | B2: Sleep Music · Ocean Waves · 432 Hz · Bottomless Night · 3 Hours | C2: Música para dormir · Olas del mar · 432 Hz · Noche sin fondo · 3 horas | D2: Dormir | E2: mar | F2: Bottomless Night · 3 Hours To accompany sleep. Ambience: ocean waves. Composed around a root of 216 Hz, the low octave of 432 Hz, in just intonation, shin mode. Breathing cycle: from 4.5 down to 3.5 breaths per minute, 40 % inhale / 60 % exhale. Original composition, synthesized from scratch, ambience included. No third-party samples. Best at low volume. Subscribe for new pieces: https://www.youtube.com/@rinchanneloficial?sub_confirmation=1 #sleepmusic #meditation #432hz | G2: Noche sin fondo · 3 horas Para acompañar el sueño. Ambiente: olas del mar. Compuesta con raíz en 216 Hz, la octava grave de 432 Hz, en entonación justa, modo shin. Ciclo respiratorio: de 4.5 a 3.5 respiraciones por minuto, inhalar 40 % / exhalar 60 %. Composición original, sintetizada desde cero: el ambiente también. Ninguna muestra procede de terceros. Mejor a volumen bajo. Suscríbete para las próximas obras: https://www.youtube.com/@rinchanneloficial?sub_confirmation=1 #sleepmusic #meditation #432hz | H2: 3 HOURS | I2: #sleepmusic #meditation #432hz | J2: sleep music, 432 hz, 432 hz music, deep sleep, insomnia, ocean waves, sea sounds, relaxing music, meditation music, calming music, ambient music, just intonation, original composition, Rin, música para dormir | M2: 432 | N2: shin | O2: grave | P2: 505716 | Q2: 110 | R2: 180 | S2: 0 | T2: python3 03-composicion/compositor.py --minutos 180 --raiz 432 --modo shin --semilla 505716 --caracter sin-cuenco --registro grave | U2: python3 03-composicion/ambiente.py audio/OBRA-001_432_shin.wav audio/OBRA-001_final.wav --fondo mar | V2: pendiente | Z2: =IFERROR(Y2/X2*1000,"")
A3: OBRA-002 | B3: Sleep Music · Ocean Waves · 528 Hz · Low Tide · 2 Hours | C3: Música para dormir · Olas del mar · 528 Hz · Marea baja · 2 horas | D3: Dormir | E3: mar | F3: Low Tide · 2 Hours To accompany sleep. Ambience: ocean waves. Composed around a root of 264 Hz, the low octave of 528 Hz, in just intonation, kumoi mode. Breathing cycle: from 4.5 down to 3.5 breaths per minute, 40 % inhale / 60 % exhale. Original composition, synthesized from scratch, ambience included. No third-party samples. Best at low volume. Subscribe for new pieces: https://www.youtube.com/@rinchanneloficial?sub_confirmation=1 #sleepmusic #meditation #528hz | G3: Marea baja · 2 horas Para acompañar el sueño. Ambiente: olas del mar. Compuesta con raíz en 264 Hz, la octava grave de 528 Hz, en entonación justa, modo kumoi. Ciclo respiratorio: de 4.5 a 3.5 respiraciones por minuto, inhalar 40 % / exhalar 60 %. Composición original, sintetizada desde cero: el ambiente también. Ninguna muestra procede de terceros. Mejor a volumen bajo. Suscríbete para las próximas obras: https://www.youtube.com/@rinchanneloficial?sub_confirmation=1 #sleepmusic #meditation #528hz | H3: 2 HOURS | I3: #sleepmusic #meditation #528hz | J3: sleep music, 528 hz, 528 hz music, deep sleep, insomnia, ocean waves, sea sounds, relaxing music, meditation music, calming music, ambient music, just intonation, original composition, Rin, música para dormir | M3: 528 | N3: kumoi | O3: grave | P3: 443547 | Q3: -70 | R3: 120 | S3: 0 | T3: python3 03-composicion/compositor.py --minutos 120 --raiz 528 --modo kumoi --semilla 443547 --caracter sin-cuenco --registro grave | U3: python3 03-composicion/ambiente.py audio/OBRA-002_528_kumoi.wav audio/OBRA-002_final.wav --fondo mar | V3: pendiente | Z3: =IFERROR(Y3/X3*1000,"")
A4: OBRA-003 | B4: Sleep Music · Ocean Waves · 396 Hz · Dark Room · 2 Hours | C4: Música para dormir · Olas del mar · 396 Hz · Cuarto oscuro · 2 horas | D4: Dormir | E4: mar | F4: Dark Room · 2 Hours To accompany sleep. Ambience: ocean waves. Composed around a root of 198 Hz, the low octave of 396 Hz, in just intonation, kumoi mode. Breathing cycle: from 4.5 down to 3.5 breaths per minute, 40 % inhale / 60 % exhale. Original composition, synthesized from scratch, ambience included. No third-party samples. Best at low volume. Subscribe for new pieces: https://www.youtube.com/@rinchanneloficial?sub_confirmation=1 #sleepmusic #meditation #396hz | G4: Cuarto oscuro · 2 horas Para acompañar el sueño. Ambiente: olas del mar. Compuesta con raíz en 198 Hz, la octava grave de 396 Hz, en entonación justa, modo kumoi. Ciclo respiratorio: de 4.5 a 3.5 respiraciones por minuto, inhalar 40 % / exhalar 60 %. Composición original, sintetizada desde cero: el ambiente también. Ninguna muestra procede de terceros. Mejor a volumen bajo. Suscríbete para las próximas obras: https://www.youtube.com/@rinchanneloficial?sub_confirmation=1 #sleepmusic #meditation #396hz | H4: 2 HOURS | I4: #sleepmusic #meditation #396hz | J4: sleep music, 396 hz, 396 hz music, deep sleep, insomnia, ocean waves, sea sounds, relaxing music, meditation music, calming music, ambient music, just intonation, original composition, Rin, música para dormir | M4: 396 | N4: kumoi | O4: grave | P4: 692584 | Q4: 180 | R4: 120 | S4: 0 | T4: python3 03-composicion/compositor.py --minutos 120 --raiz 396 --modo kumoi --semilla 692584 --caracter sin-cuenco --registro grave | U4: python3 03-composicion/ambiente.py audio/OBRA-003_396_kumoi.wav audio/OBRA-003_final.wav --fondo mar | V4: pendiente | Z4: =IFERROR(Y4/X4*1000,"")
A5: OBRA-004 | B5: Sleep Music · Ocean Waves · 528 Hz · No One Awake · 3 Hours | C5: Música para dormir · Olas del mar · 528 Hz · Nadie despierto · 3 horas | D5: Dormir | E5: mar | F5: No One Awake · 3 Hours To accompany sleep. Ambience: ocean waves. Composed around a root of 264 Hz, the low octave of 528 Hz, in just intonation, shin mode. Breathing cycle: from 4.5 down to 3.5 breaths per minute, 40 % inhale / 60 % exhale. Original composition, synthesized from scratch, ambience included. No third-party samples. Best at low volume. Subscribe for new pieces: https://www.youtube.com/@rinchanneloficial?sub_confirmation=1 #sleepmusic #meditation #528hz | G5: Nadie despierto · 3 horas Para acompañar el sueño. Ambiente: olas del mar. Compuesta con raíz en 264 Hz, la octava grave de 528 Hz, en entonación justa, modo shin. Ciclo respiratorio: de 4.5 a 3.5 respiraciones por minuto, inhalar 40 % / exhalar 60 %. Composición original, sintetizada desde cero: el ambiente también. Ninguna muestra procede de terceros. Mejor a volumen bajo. Suscríbete para las próximas obras: https://www.youtube.com/@rinchanneloficial?sub_confirmation=1 #sleepmusic #meditation #528hz | H5: 3 HOURS | I5: #sleepmusic #meditation #528hz | J5: sleep music, 528 hz, 528 hz music, deep sleep, insomnia, ocean waves, sea sounds, relaxing music, meditation music, calming music, ambient music, just intonation, original composition, Rin, música para dormir | M5: 528 | N5: shin | O5: grave | P5: 751043 | Q5: 35 | R5: 180 | S5: 0 | T5: python3 03-composicion/compositor.py --minutos 180 --raiz 528 --modo shin --semilla 751043 --caracter sin-cuenco --registro grave | U5: python3 03-composicion/ambiente.py audio/OBRA-004_528_shin.wav audio/OBRA-004_final.wav --fondo mar | V5: pendiente | Z5: =IFERROR(Y5/X5*1000,"")
A6: OBRA-005 | B6: Sleep Music · Ocean Waves · 432 Hz · Winter Breath · 2 Hours | C6: Música para dormir · Olas del mar · 432 Hz · Respiración de invierno · 2 horas | D6: Dormir | E6: mar | F6: Winter Breath · 2 Hours To accompany sleep. Ambience: ocean waves. Composed around a root of 216 Hz, the low octave of 432 Hz, in just intonation, kumoi mode. Breathing cycle: from 4.5 down to 3.5 breaths per minute, 40 % inhale / 60 % exhale. Original composition, synthesized from scratch, ambience included. No third-party samples. Best at low volume. Subscribe for new pieces: https://www.youtube.com/@rinchanneloficial?sub_confirmation=1 #sleepmusic #meditation #432hz | G6: Respiración de invierno · 2 horas Para acompañar el sueño. Ambiente: olas del mar. Compuesta con raíz en 216 Hz, la octava grave de 432 Hz, en entonación justa, modo kumoi. Ciclo respiratorio: de 4.5 a 3.5 respiraciones por minuto, inhalar 40 % / exhalar 60 %. Composición original, sintetizada desde cero: el ambiente también. Ninguna muestra procede de terceros. Mejor a volumen bajo. Suscríbete para las próximas obras: https://www.youtube.com/@rinchanneloficial?sub_confirmation=1 #sleepmusic #meditation #432hz | H6: 2 HOURS | I6: #sleepmusic #meditation #432hz | J6: sleep music, 432 hz, 432 hz music, deep sleep, insomnia, ocean waves, sea sounds, relaxing music, meditation music, calming music, ambient music, just intonation, original composition, Rin, música para dormir | M6: 432 | N6: kumoi | O6: grave | P6: 531725 | Q6: -110 | R6: 120 | S6: 0 | T6: python3 03-composicion/compositor.py --minutos 120 --raiz 432 --modo kumoi --semilla 531725 --caracter sin-cuenco --registro grave | U6: python3 03-composicion/ambiente.py audio/OBRA-005_432_kumoi.wav audio/OBRA-005_final.wav --fondo mar | V6: pendiente | Z6: =IFERROR(Y6/X6*1000,"")
A7: OBRA-006 | B7: Sleep Music · Ocean Waves · 417 Hz · Before Dawn · 90 Minutes | C7: Música para dormir · Olas del mar · 417 Hz · Antes del alba · 90 minutos | D7: Dormir | E7: mar | F7: Before Dawn · 90 Minutes To accompany sleep. Ambience: ocean waves. Composed around a root of 208.5 Hz, the low octave of 417 Hz, in just intonation, kumoi mode. Breathing cycle: from 4.5 down to 3.5 breaths per minute, 40 % inhale / 60 % exhale. Original composition, synthesized from scratch, ambience included. No third-party samples. Best at low volume. Subscribe for new pieces: https://www.youtube.com/@rinchanneloficial?sub_confirmation=1 #sleepmusic #meditation #417hz | G7: Antes del alba · 90 minutos Para acompañar el sueño. Ambiente: olas del mar. Compuesta con raíz en 208.5 Hz, la octava grave de 417 Hz, en entonación justa, modo kumoi. Ciclo respiratorio: de 4.5 a 3.5 respiraciones por minuto, inhalar 40 % / exhalar 60 %. Composición original, sintetizada desde cero: el ambiente también. Ninguna muestra procede de terceros. Mejor a volumen bajo. Suscríbete para las próximas obras: https://www.youtube.com/@rinchanneloficial?sub_confirmation=1 #sleepmusic #meditation #417hz | H7: 90 MIN | I7: #sleepmusic #meditation #417hz | J7: sleep music, 417 hz, 417 hz music, deep sleep, insomnia, ocean waves, sea sounds, relaxing music, meditation music, calming music, ambient music, just intonation, original composition, Rin, música para dormir | L7: https://youtu.be/cECOoUGLqes | M7: 417 | N7: kumoi | O7: grave | P7: 813147 | Q7: 0 | R7: 90 | S7: 0 | T7: python3 03-composicion/compositor.py --minutos 90 --raiz 417 --modo kumoi --semilla 813147 --caracter sin-cuenco --registro grave | U7: python3 03-composicion/ambiente.py audio/OBRA-006_417_kumoi.wav audio/OBRA-006_final.wav --fondo mar | V7: publicada | W7: 2026-09-26 | Z7: =IFERROR(Y7/X7*1000,"")
A8: OBRA-007 | B8: Sleep Music · Ocean Waves · 396 Hz · Slow Weight · 2 Hours | C8: Música para dormir · Olas del mar · 396 Hz · Peso lento · 2 horas | D8: Dormir | E8: mar | F8: Slow Weight · 2 Hours To accompany sleep. Ambience: ocean waves. Composed around a root of 198 Hz, the low octave of 396 Hz, in just intonation, shin mode. Breathing cycle: from 4.5 down to 3.5 breaths per minute, 40 % inhale / 60 % exhale. Original composition, synthesized from scratch, ambience included. No third-party samples. Best at low volume. Subscribe for new pieces: https://www.youtube.com/@rinchanneloficial?sub_confirmation=1 #sleepmusic #meditation #396hz | G8: Peso lento · 2 horas Para acompañar el sueño. Ambiente: olas del mar. Compuesta con raíz en 198 Hz, la octava grave de 396 Hz, en entonación justa, modo shin. Ciclo respiratorio: de 4.5 a 3.5 respiraciones por minuto, inhalar 40 % / exhalar 60 %. Composición original, sintetizada desde cero: el ambiente también. Ninguna muestra procede de terceros. Mejor a volumen bajo. Suscríbete para las próximas obras: https://www.youtube.com/@rinchanneloficial?sub_confirmation=1 #sleepmusic #meditation #396hz | H8: 2 HOURS | I8: #sleepmusic #meditation #396hz | J8: sleep music, 396 hz, 396 hz music, deep sleep, insomnia, ocean waves, sea sounds, relaxing music, meditation music, calming music, ambient music, just intonation, original composition, Rin, música para dormir | M8: 396 | N8: shin | O8: grave | P8: 885916 | Q8: 70 | R8: 120 | S8: 0 | T8: python3 03-composicion/compositor.py --minutos 120 --raiz 396 --modo shin --semilla 885916 --caracter sin-cuenco --registro grave | U8: python3 03-composicion/ambiente.py audio/OBRA-007_396_shin.wav audio/OBRA-007_final.wav --fondo mar | V8: pendiente | Z8: =IFERROR(Y8/X8*1000,"")
A9: OBRA-008 | B9: Sleep Music · Ocean Waves · 432 Hz · The Sleeping House · 3 Hours | C9: Música para dormir · Olas del mar · 432 Hz · La casa dormida · 3 horas | D9: Dormir | E9: mar | F9: The Sleeping House · 3 Hours To accompany sleep. Ambience: ocean waves. Composed around a root of 216 Hz, the low octave of 432 Hz, in just intonation, kumoi mode. Breathing cycle: from 4.5 down to 3.5 breaths per minute, 40 % inhale / 60 % exhale. Original composition, synthesized from scratch, ambience included. No third-party samples. Best at low volume. Subscribe for new pieces: https://www.youtube.com/@rinchanneloficial?sub_confirmation=1 #sleepmusic #meditation #432hz | G9: La casa dormida · 3 horas Para acompañar el sueño. Ambiente: olas del mar. Compuesta con raíz en 216 Hz, la octava grave de 432 Hz, en entonación justa, modo kumoi. Ciclo respiratorio: de 4.5 a 3.5 respiraciones por minuto, inhalar 40 % / exhalar 60 %. Composición original, sintetizada desde cero: el ambiente también. Ninguna muestra procede de terceros. Mejor a volumen bajo. Suscríbete para las próximas obras: https://www.youtube.com/@rinchanneloficial?sub_confirmation=1 #sleepmusic #meditation #432hz | H9: 3 HOURS | I9: #sleepmusic #meditation #432hz | J9: sleep music, 432 hz, 432 hz music, deep sleep, insomnia, ocean waves, sea sounds, relaxing music, meditation music, calming music, ambient music, just intonation, original composition, Rin, música para dormir | M9: 432 | N9: kumoi | O9: grave | P9: 295910 | Q9: 150 | R9: 180 | S9: 0 | T9: python3 03-composicion/compositor.py --minutos 180 --raiz 432 --modo kumoi --semilla 295910 --caracter sin-cuenco --registro grave | U9: python3 03-composicion/ambiente.py audio/OBRA-008_432_kumoi.wav audio/OBRA-008_final.wav --fondo mar | V9: pendiente | Z9: =IFERROR(Y9/X9*1000,"")
A10: OBRA-009 | B10: Music for Anxiety · Ocean and Birds · 396 Hz · Just Exhale · 25 Minutes | C10: Música para momentos de ansiedad · Mar y pájaros · 396 Hz · Solo exhalar · 25 minutos | D10: Ansiedad | E10: mar-aves | F10: Just Exhale · 25 Minutes To accompany a pause when your mind won't stop. Ambience: ocean and birds. Composed around a root of 396 Hz, in just intonation, kumoi mode. Breathing cycle: from 6.0 down to 4.5 breaths per minute, 40 % inhale / 60 % exhale. Original composition, synthesized from scratch, ambience included. No third-party samples. Best at low volume. Subscribe for new pieces: https://www.youtube.com/@rinchanneloficial?sub_confirmation=1 #relaxingmusic #meditation #396hz | G10: Solo exhalar · 25 minutos Para acompañar un momento de pausa cuando la cabeza no para. Ambiente: mar y pájaros. Compuesta con raíz en 396 Hz, en entonación justa, modo kumoi. Ciclo respiratorio: de 6.0 a 4.5 respiraciones por minuto, inhalar 40 % / exhalar 60 %. Composición original, sintetizada desde cero: el ambiente también. Ninguna muestra procede de terceros. Mejor a volumen bajo. Suscríbete para las próximas obras: https://www.youtube.com/@rinchanneloficial?sub_confirmation=1 #relaxingmusic #meditation #396hz | H10: 25 MIN | I10: #relaxingmusic #meditation #396hz | J10: music for anxiety, 396 hz, 396 hz music, anxiety relief, stress relief, calming music, ocean waves, birdsong, nature sounds, relaxing music, meditation music, ambient music, just intonation, original composition, Rin, música para momentos de ansiedad | M10: 396 | N10: kumoi | O10: medio | P10: 555819 | Q10: 110 | R10: 25 | S10: 0 | T10: python3 03-composicion/compositor.py --minutos 25 --raiz 396 --modo kumoi --semilla 555819 --caracter sin-cuenco | U10: python3 03-composicion/capas.py aves 1540 audio/OBRA-009_capa.wav --semilla 555819 --raiz 396 && python3 03-composicion/ambiente.py audio/OBRA-009_396_kumoi.wav audio/OBRA-009_final.wav --fondo mar --nivel-capa -4 --capa audio/OBRA-009_capa.wav | V10: pendiente | Z10: =IFERROR(Y10/X10*1000,"")
A11: OBRA-010 | B11: Music for Anxiety · Zen Temple · 432 Hz · Slowing Down · 30 Minutes | C11: Música para momentos de ansiedad · Templo zen · 432 Hz · Bajar el ritmo · 30 minutos | D11: Ansiedad | E11: zen | F11: Slowing Down · 30 Minutes To accompany a pause when your mind won't stop. Ambience: zen temple. Composed around a root of 432 Hz, in just intonation, hirajoshi mode. Breathing cycle: from 6.0 down to 4.5 breaths per minute, 40 % inhale / 60 % exhale. Original composition, synthesized from scratch, ambience included. No third-party samples. Best at low volume. Subscribe for new pieces: https://www.youtube.com/@rinchanneloficial?sub_confirmation=1 #relaxingmusic #meditation #432hz | G11: Bajar el ritmo · 30 minutos Para acompañar un momento de pausa cuando la cabeza no para. Ambiente: templo zen. Compuesta con raíz en 432 Hz, en entonación justa, modo hirajoshi. Ciclo respiratorio: de 6.0 a 4.5 respiraciones por minuto, inhalar 40 % / exhalar 60 %. Composición original, sintetizada desde cero: el ambiente también. Ninguna muestra procede de terceros. Mejor a volumen bajo. Suscríbete para las próximas obras: https://www.youtube.com/@rinchanneloficial?sub_confirmation=1 #relaxingmusic #meditation #432hz | H11: 30 MIN | I11: #relaxingmusic #meditation #432hz | J11: music for anxiety, 432 hz, 432 hz music, anxiety relief, stress relief, calming music, zen temple, temple bells, wind chimes, relaxing music, meditation music, ambient music, just intonation, original composition, Rin, música para momentos de ansiedad | M11: 432 | N11: hirajoshi | O11: medio | P11: 739461 | Q11: 110 | R11: 30 | S11: 0 | T11: python3 03-composicion/compositor.py --minutos 30 --raiz 432 --modo hirajoshi --semilla 739461 --caracter sin-cuenco | U11: python3 03-composicion/capas.py zen 1840 audio/OBRA-010_capa.wav --semilla 739461 --raiz 432 --densidad 1.4 && python3 03-composicion/ambiente.py audio/OBRA-010_432_hirajoshi.wav audio/OBRA-010_final.wav --fondo mar --nivel-fondo -7 --nivel-capa 2 --capa audio/OBRA-010_capa.wav | V11: pendiente | Z11: =IFERROR(Y11/X11*1000,"")
A12: OBRA-011 | B12: Music for Anxiety · Ocean and Birds · 528 Hz · Four and Six · 20 Minutes | C12: Música para momentos de ansiedad · Mar y pájaros · 528 Hz · Cuatro y seis · 20 minutos | D12: Ansiedad | E12: mar-aves | F12: Four and Six · 20 Minutes To accompany a pause when your mind won't stop. Ambience: ocean and birds. Composed around a root of 528 Hz, in just intonation, hirajoshi mode. Breathing cycle: from 6.0 down to 4.5 breaths per minute, 40 % inhale / 60 % exhale. Original composition, synthesized from scratch, ambience included. No third-party samples. Best at low volume. Subscribe for new pieces: https://www.youtube.com/@rinchanneloficial?sub_confirmation=1 #relaxingmusic #meditation #528hz | G12: Cuatro y seis · 20 minutos Para acompañar un momento de pausa cuando la cabeza no para. Ambiente: mar y pájaros. Compuesta con raíz en 528 Hz, en entonación justa, modo hirajoshi. Ciclo respiratorio: de 6.0 a 4.5 respiraciones por minuto, inhalar 40 % / exhalar 60 %. Composición original, sintetizada desde cero: el ambiente también. Ninguna muestra procede de terceros. Mejor a volumen bajo. Suscríbete para las próximas obras: https://www.youtube.com/@rinchanneloficial?sub_confirmation=1 #relaxingmusic #meditation #528hz | H12: 20 MIN | I12: #relaxingmusic #meditation #528hz | J12: music for anxiety, 528 hz, 528 hz music, anxiety relief, stress relief, calming music, ocean waves, birdsong, nature sounds, relaxing music, meditation music, ambient music, just intonation, original composition, Rin, música para momentos de ansiedad | M12: 528 | N12: hirajoshi | O12: medio | P12: 913368 | Q12: -70 | R12: 20 | S12: 0 | T12: python3 03-composicion/compositor.py --minutos 20 --raiz 528 --modo hirajoshi --semilla 913368 --caracter sin-cuenco | U12: python3 03-composicion/capas.py aves 1240 audio/OBRA-011_capa.wav --semilla 913368 --raiz 528 && python3 03-composicion/ambiente.py audio/OBRA-011_528_hirajoshi.wav audio/OBRA-011_final.wav --fondo mar --nivel-capa -4 --capa audio/OBRA-011_capa.wav | V12: pendiente | Z12: =IFERROR(Y12/X12*1000,"")
A13: OBRA-012 | B13: Music for Anxiety · Zen Temple · 528 Hz · A Brief Pause · 10 Minutes | C13: Música para momentos de ansiedad · Templo zen · 528 Hz · Pausa breve · 10 minutos | D13: Ansiedad | E13: zen | F13: A Brief Pause · 10 Minutes To accompany a pause when your mind won't stop. Ambience: zen temple. Composed around a root of 528 Hz, in just intonation, shin mode. Breathing cycle: from 6.0 down to 4.5 breaths per minute, 40 % inhale / 60 % exhale. Original composition, synthesized from scratch, ambience included. No third-party samples. Best at low volume. Subscribe for new pieces: https://www.youtube.com/@rinchanneloficial?sub_confirmation=1 #relaxingmusic #meditation #528hz | G13: Pausa breve · 10 minutos Para acompañar un momento de pausa cuando la cabeza no para. Ambiente: templo zen. Compuesta con raíz en 528 Hz, en entonación justa, modo shin. Ciclo respiratorio: de 6.0 a 4.5 respiraciones por minuto, inhalar 40 % / exhalar 60 %. Composición original, sintetizada desde cero: el ambiente también. Ninguna muestra procede de terceros. Mejor a volumen bajo. Suscríbete para las próximas obras: https://www.youtube.com/@rinchanneloficial?sub_confirmation=1 #relaxingmusic #meditation #528hz | H13: 10 MIN | I13: #relaxingmusic #meditation #528hz | J13: music for anxiety, 528 hz, 528 hz music, anxiety relief, stress relief, calming music, zen temple, temple bells, wind chimes, relaxing music, meditation music, ambient music, just intonation, original composition, Rin, música para momentos de ansiedad | L13: https://youtu.be/-ywSggvwt2E | M13: 528 | N13: shin | O13: medio | P13: 43734 | Q13: 0 | R13: 10 | S13: 0 | T13: python3 03-composicion/compositor.py --minutos 10 --raiz 528 --modo shin --semilla 43734 --caracter sin-cuenco | U13: python3 03-composicion/capas.py zen 640 audio/OBRA-012_capa.wav --semilla 43734 --raiz 528 --densidad 1.4 && python3 03-composicion/ambiente.py audio/OBRA-012_528_shin.wav audio/OBRA-012_final.wav --fondo mar --nivel-fondo -7 --nivel-capa 2 --capa audio/OBRA-012_capa.wav | V13: publicada | W13: 2026-09-23 | Z13: =IFERROR(Y13/X13*1000,"")
A14: OBRA-013 | B14: Music for Anxiety · Ocean and Birds · 432 Hz · Count to Six · 20 Minutes | C14: Música para momentos de ansiedad · Mar y pájaros · 432 Hz · Contar hasta seis · 20 minutos | D14: Ansiedad | E14: mar-aves | F14: Count to Six · 20 Minutes To accompany a pause when your mind won't stop. Ambience: ocean and birds. Composed around a root of 432 Hz, in just intonation, hirajoshi mode. Breathing cycle: from 6.0 down to 4.5 breaths per minute, 40 % inhale / 60 % exhale. Original composition, synthesized from scratch, ambience included. No third-party samples. Best at low volume. Subscribe for new pieces: https://www.youtube.com/@rinchanneloficial?sub_confirmation=1 #relaxingmusic #meditation #432hz | G14: Contar hasta seis · 20 minutos Para acompañar un momento de pausa cuando la cabeza no para. Ambiente: mar y pájaros. Compuesta con raíz en 432 Hz, en entonación justa, modo hirajoshi. Ciclo respiratorio: de 6.0 a 4.5 respiraciones por minuto, inhalar 40 % / exhalar 60 %. Composición original, sintetizada desde cero: el ambiente también. Ninguna muestra procede de terceros. Mejor a volumen bajo. Suscríbete para las próximas obras: https://www.youtube.com/@rinchanneloficial?sub_confirmation=1 #relaxingmusic #meditation #432hz | H14: 20 MIN | I14: #relaxingmusic #meditation #432hz | J14: music for anxiety, 432 hz, 432 hz music, anxiety relief, stress relief, calming music, ocean waves, birdsong, nature sounds, relaxing music, meditation music, ambient music, just intonation, original composition, Rin, música para momentos de ansiedad | M14: 432 | N14: hirajoshi | O14: medio | P14: 627771 | Q14: 180 | R14: 20 | S14: 0 | T14: python3 03-composicion/compositor.py --minutos 20 --raiz 432 --modo hirajoshi --semilla 627771 --caracter sin-cuenco | U14: python3 03-composicion/capas.py aves 1240 audio/OBRA-013_capa.wav --semilla 627771 --raiz 432 && python3 03-composicion/ambiente.py audio/OBRA-013_432_hirajoshi.wav audio/OBRA-013_final.wav --fondo mar --nivel-capa -4 --capa audio/OBRA-013_capa.wav | V14: pendiente | Z14: =IFERROR(Y14/X14*1000,"")
A15: OBRA-014 | B15: Music for Anxiety · Zen Temple · 528 Hz · In and Out · 20 Minutes | C15: Música para momentos de ansiedad · Templo zen · 528 Hz · Entrada y salida · 20 minutos | D15: Ansiedad | E15: zen | F15: In and Out · 20 Minutes To accompany a pause when your mind won't stop. Ambience: zen temple. Composed around a root of 528 Hz, in just intonation, yo mode. Breathing cycle: from 6.0 down to 4.5 breaths per minute, 40 % inhale / 60 % exhale. Original composition, synthesized from scratch, ambience included. No third-party samples. Best at low volume. Subscribe for new pieces: https://www.youtube.com/@rinchanneloficial?sub_confirmation=1 #relaxingmusic #meditation #528hz | G15: Entrada y salida · 20 minutos Para acompañar un momento de pausa cuando la cabeza no para. Ambiente: templo zen. Compuesta con raíz en 528 Hz, en entonación justa, modo yo. Ciclo respiratorio: de 6.0 a 4.5 respiraciones por minuto, inhalar 40 % / exhalar 60 %. Composición original, sintetizada desde cero: el ambiente también. Ninguna muestra procede de terceros. Mejor a volumen bajo. Suscríbete para las próximas obras: https://www.youtube.com/@rinchanneloficial?sub_confirmation=1 #relaxingmusic #meditation #528hz | H15: 20 MIN | I15: #relaxingmusic #meditation #528hz | J15: music for anxiety, 528 hz, 528 hz music, anxiety relief, stress relief, calming music, zen temple, temple bells, wind chimes, relaxing music, meditation music, ambient music, just intonation, original composition, Rin, música para momentos de ansiedad | M15: 528 | N15: yo | O15: medio | P15: 310137 | Q15: -70 | R15: 20 | S15: 0 | T15: python3 03-composicion/compositor.py --minutos 20 --raiz 528 --modo yo --semilla 310137 --caracter sin-cuenco | U15: python3 03-composicion/capas.py zen 1240 audio/OBRA-014_capa.wav --semilla 310137 --raiz 528 --densidad 1.4 && python3 03-composicion/ambiente.py audio/OBRA-014_528_yo.wav audio/OBRA-014_final.wav --fondo mar --nivel-fondo -7 --nivel-capa 2 --capa audio/OBRA-014_capa.wav | V15: pendiente | Z15: =IFERROR(Y15/X15*1000,"")
A16: OBRA-015 | B16: Music for Anxiety · Ocean and Birds · 639 Hz · Before You Begin · 15 Minutes | C16: Música para momentos de ansiedad · Mar y pájaros · 639 Hz · Antes de empezar · 15 minutos | D16: Ansiedad | E16: mar-aves | F16: Before You Begin · 15 Minutes To accompany a pause when your mind won't stop. Ambience: ocean and birds. Composed around a root of 639 Hz, in just intonation, yo mode. Breathing cycle: from 6.0 down to 4.5 breaths per minute, 40 % inhale / 60 % exhale. Original composition, synthesized from scratch, ambience included. No third-party samples. Best at low volume. Subscribe for new pieces: https://www.youtube.com/@rinchanneloficial?sub_confirmation=1 #relaxingmusic #meditation #639hz | G16: Antes de empezar · 15 minutos Para acompañar un momento de pausa cuando la cabeza no para. Ambiente: mar y pájaros. Compuesta con raíz en 639 Hz, en entonación justa, modo yo. Ciclo respiratorio: de 6.0 a 4.5 respiraciones por minuto, inhalar 40 % / exhalar 60 %. Composición original, sintetizada desde cero: el ambiente también. Ninguna muestra procede de terceros. Mejor a volumen bajo. Suscríbete para las próximas obras: https://www.youtube.com/@rinchanneloficial?sub_confirmation=1 #relaxingmusic #meditation #639hz | H16: 15 MIN | I16: #relaxingmusic #meditation #639hz | J16: music for anxiety, 639 hz, 639 hz music, anxiety relief, stress relief, calming music, ocean waves, birdsong, nature sounds, relaxing music, meditation music, ambient music, just intonation, original composition, Rin, música para momentos de ansiedad | L16: https://youtu.be/nN2uPKczsrc | M16: 639 | N16: yo | O16: medio | P16: 592463 | Q16: 0 | R16: 15 | S16: 0 | T16: python3 03-composicion/compositor.py --minutos 15 --raiz 639 --modo yo --semilla 592463 --caracter sin-cuenco | U16: python3 03-composicion/capas.py aves 940 audio/OBRA-015_capa.wav --semilla 592463 --raiz 639 && python3 03-composicion/ambiente.py audio/OBRA-015_639_yo.wav audio/OBRA-015_final.wav --fondo mar --nivel-capa -4 --capa audio/OBRA-015_capa.wav | V16: publicada | W16: 2026-09-23 | Z16: =IFERROR(Y16/X16*1000,"")
A17: OBRA-016 | B17: Music for Anxiety · Rain on Leaves · 417 Hz · End of the Day · 30 Minutes | C17: Música para momentos de ansiedad · Lluvia sobre hojas · 417 Hz · El final del día · 30 minutos | D17: Ansiedad | E17: lluvia-tambor | F17: End of the Day · 30 Minutes To accompany a pause when your mind won't stop. Ambience: rain on leaves. Composed around a root of 417 Hz, in just intonation, kumoi mode. Breathing cycle: from 6.0 down to 4.5 breaths per minute, 40 % inhale / 60 % exhale. Original composition, synthesized from scratch, ambience included. No third-party samples. Best at low volume. Subscribe for new pieces: https://www.youtube.com/@rinchanneloficial?sub_confirmation=1 #relaxingmusic #meditation #417hz | G17: El final del día · 30 minutos Para acompañar un momento de pausa cuando la cabeza no para. Ambiente: lluvia sobre hojas. Compuesta con raíz en 417 Hz, en entonación justa, modo kumoi. Ciclo respiratorio: de 6.0 a 4.5 respiraciones por minuto, inhalar 40 % / exhalar 60 %. Composición original, sintetizada desde cero: el ambiente también. Ninguna muestra procede de terceros. Mejor a volumen bajo. Suscríbete para las próximas obras: https://www.youtube.com/@rinchanneloficial?sub_confirmation=1 #relaxingmusic #meditation #417hz | H17: 30 MIN | I17: #relaxingmusic #meditation #417hz | J17: music for anxiety, 417 hz, 417 hz music, anxiety relief, stress relief, calming music, rain sounds, rain on leaves, shamanic drum, relaxing music, meditation music, ambient music, just intonation, original composition, Rin, música para momentos de ansiedad | M17: 417 | N17: kumoi | O17: medio | P17: 250697 | Q17: 110 | R17: 30 | S17: 0 | T17: python3 03-composicion/compositor.py --minutos 30 --raiz 417 --modo kumoi --semilla 250697 --caracter sin-cuenco | U17: python3 03-composicion/capas.py ancestral 1840 audio/OBRA-016_capa.wav --semilla 250697 --raiz 417 && python3 03-composicion/ambiente.py audio/OBRA-016_417_kumoi.wav audio/OBRA-016_final.wav --fondo fuego --nivel-capa 0 --nivel-obra -20 --capa audio/OBRA-016_capa.wav | V17: pendiente | Z17: =IFERROR(Y17/X17*1000,"")
A18: OBRA-017 | B18: Meditation Music · Zen Temple · 417 Hz · Empty Temple · 45 Minutes | C18: Música para meditar · Templo zen · 417 Hz · Templo vacío · 45 minutos | D18: Meditar | E18: zen | F18: Empty Temple · 45 Minutes To accompany a meditation practice. Ambience: zen temple. Composed around a root of 417 Hz, in just intonation, hirajoshi mode. Breathing cycle: from 5.5 down to 4.5 breaths per minute, 40 % inhale / 60 % exhale. Original composition, synthesized from scratch, ambience included. No third-party samples. Best at low volume. Subscribe for new pieces: https://www.youtube.com/@rinchanneloficial?sub_confirmation=1 #meditationmusic #meditation #417hz | G18: Templo vacío · 45 minutos Para acompañar una práctica de meditación. Ambiente: templo zen. Compuesta con raíz en 417 Hz, en entonación justa, modo hirajoshi. Ciclo respiratorio: de 5.5 a 4.5 respiraciones por minuto, inhalar 40 % / exhalar 60 %. Composición original, sintetizada desde cero: el ambiente también. Ninguna muestra procede de terceros. Mejor a volumen bajo. Suscríbete para las próximas obras: https://www.youtube.com/@rinchanneloficial?sub_confirmation=1 #meditationmusic #meditation #417hz | H18: 45 MIN | I18: #meditationmusic #meditation #417hz | J18: meditation music, 417 hz, 417 hz music, mindfulness, zen music, yoga music, zen temple, temple bells, wind chimes, relaxing music, calming music, ambient music, just intonation, original composition, Rin, música para meditar | M18: 417 | N18: hirajoshi | O18: medio | P18: 714152 | Q18: 180 | R18: 45 | S18: 0 | T18: python3 03-composicion/compositor.py --minutos 45 --raiz 417 --modo hirajoshi --semilla 714152 --caracter sin-cuenco | U18: python3 03-composicion/capas.py zen 2740 audio/OBRA-017_capa.wav --semilla 714152 --raiz 417 --densidad 1.4 && python3 03-composicion/ambiente.py audio/OBRA-017_417_hirajoshi.wav audio/OBRA-017_final.wav --fondo mar --nivel-fondo -7 --nivel-capa 2 --capa audio/OBRA-017_capa.wav | V18: pendiente | Z18: =IFERROR(Y18/X18*1000,"")
A19: OBRA-018 | B19: Meditation Music · Zen Temple · 528 Hz · Seven Bells · 45 Minutes | C19: Música para meditar · Templo zen · 528 Hz · Siete campanas · 45 minutos | D19: Meditar | E19: zen | F19: Seven Bells · 45 Minutes To accompany a meditation practice. Ambience: zen temple. Composed around a root of 528 Hz, in just intonation, hirajoshi mode. Breathing cycle: from 5.5 down to 4.5 breaths per minute, 40 % inhale / 60 % exhale. Original composition, synthesized from scratch, ambience included. No third-party samples. Best at low volume. Subscribe for new pieces: https://www.youtube.com/@rinchanneloficial?sub_confirmation=1 #meditationmusic #meditation #528hz | G19: Siete campanas · 45 minutos Para acompañar una práctica de meditación. Ambiente: templo zen. Compuesta con raíz en 528 Hz, en entonación justa, modo hirajoshi. Ciclo respiratorio: de 5.5 a 4.5 respiraciones por minuto, inhalar 40 % / exhalar 60 %. Composición original, sintetizada desde cero: el ambiente también. Ninguna muestra procede de terceros. Mejor a volumen bajo. Suscríbete para las próximas obras: https://www.youtube.com/@rinchanneloficial?sub_confirmation=1 #meditationmusic #meditation #528hz | H19: 45 MIN | I19: #meditationmusic #meditation #528hz | J19: meditation music, 528 hz, 528 hz music, mindfulness, zen music, yoga music, zen temple, temple bells, wind chimes, relaxing music, calming music, ambient music, just intonation, original composition, Rin, música para meditar | M19: 528 | N19: hirajoshi | O19: medio | P19: 735455 | Q19: 35 | R19: 45 | S19: 0 | T19: python3 03-composicion/compositor.py --minutos 45 --raiz 528 --modo hirajoshi --semilla 735455 --caracter sin-cuenco | U19: python3 03-composicion/capas.py zen 2740 audio/OBRA-018_capa.wav --semilla 735455 --raiz 528 --densidad 1.4 && python3 03-composicion/ambiente.py audio/OBRA-018_528_hirajoshi.wav audio/OBRA-018_final.wav --fondo mar --nivel-fondo -7 --nivel-capa 2 --capa audio/OBRA-018_capa.wav | V19: pendiente | Z19: =IFERROR(Y19/X19*1000,"")
A20: OBRA-019 | B20: Meditation Music · Zen Temple · 432 Hz · Metal and Air · 1 Hour | C20: Música para meditar · Templo zen · 432 Hz · Metal y aire · 1 hora | D20: Meditar | E20: zen | F20: Metal and Air · 1 Hour To accompany a meditation practice. Ambience: zen temple. Composed around a root of 432 Hz, in just intonation, shin mode. Breathing cycle: from 5.5 down to 4.5 breaths per minute, 40 % inhale / 60 % exhale. Original composition, synthesized from scratch, ambience included. No third-party samples. Best at low volume. Subscribe for new pieces: https://www.youtube.com/@rinchanneloficial?sub_confirmation=1 #meditationmusic #meditation #432hz | G20: Metal y aire · 1 hora Para acompañar una práctica de meditación. Ambiente: templo zen. Compuesta con raíz en 432 Hz, en entonación justa, modo shin. Ciclo respiratorio: de 5.5 a 4.5 respiraciones por minuto, inhalar 40 % / exhalar 60 %. Composición original, sintetizada desde cero: el ambiente también. Ninguna muestra procede de terceros. Mejor a volumen bajo. Suscríbete para las próximas obras: https://www.youtube.com/@rinchanneloficial?sub_confirmation=1 #meditationmusic #meditation #432hz | H20: 60 MIN | I20: #meditationmusic #meditation #432hz | J20: meditation music, 432 hz, 432 hz music, mindfulness, zen music, yoga music, zen temple, temple bells, wind chimes, relaxing music, calming music, ambient music, just intonation, original composition, Rin, música para meditar | M20: 432 | N20: shin | O20: medio | P20: 627577 | Q20: -110 | R20: 60 | S20: 0 | T20: python3 03-composicion/compositor.py --minutos 60 --raiz 432 --modo shin --semilla 627577 --caracter sin-cuenco | U20: python3 03-composicion/capas.py zen 3640 audio/OBRA-019_capa.wav --semilla 627577 --raiz 432 --densidad 1.4 && python3 03-composicion/ambiente.py audio/OBRA-019_432_shin.wav audio/OBRA-019_final.wav --fondo mar --nivel-fondo -7 --nivel-capa 2 --capa audio/OBRA-019_capa.wav | V20: pendiente | Z20: =IFERROR(Y20/X20*1000,"")
A21: OBRA-020 | B21: Meditation Music · Rain on Leaves · 528 Hz · Strike and Silence · 30 Minutes | C21: Música para meditar · Lluvia sobre hojas · 528 Hz · Golpe y silencio · 30 minutos | D21: Meditar | E21: lluvia-tambor | F21: Strike and Silence · 30 Minutes To accompany a meditation practice. Ambience: rain on leaves. Composed around a root of 528 Hz, in just intonation, shin mode. Breathing cycle: from 5.5 down to 4.5 breaths per minute, 40 % inhale / 60 % exhale. Original composition, synthesized from scratch, ambience included. No third-party samples. Best at low volume. Subscribe for new pieces: https://www.youtube.com/@rinchanneloficial?sub_confirmation=1 #meditationmusic #meditation #528hz | G21: Golpe y silencio · 30 minutos Para acompañar una práctica de meditación. Ambiente: lluvia sobre hojas. Compuesta con raíz en 528 Hz, en entonación justa, modo shin. Ciclo respiratorio: de 5.5 a 4.5 respiraciones por minuto, inhalar 40 % / exhalar 60 %. Composición original, sintetizada desde cero: el ambiente también. Ninguna muestra procede de terceros. Mejor a volumen bajo. Suscríbete para las próximas obras: https://www.youtube.com/@rinchanneloficial?sub_confirmation=1 #meditationmusic #meditation #528hz | H21: 30 MIN | I21: #meditationmusic #meditation #528hz | J21: meditation music, 528 hz, 528 hz music, mindfulness, zen music, yoga music, rain sounds, rain on leaves, shamanic drum, relaxing music, calming music, ambient music, just intonation, original composition, Rin, música para meditar | L21: https://youtu.be/QvcXe4ZDq8o | M21: 528 | N21: shin | O21: medio | P21: 632595 | Q21: 0 | R21: 30 | S21: 0 | T21: python3 03-composicion/compositor.py --minutos 30 --raiz 528 --modo shin --semilla 632595 --caracter sin-cuenco | U21: python3 03-composicion/capas.py ancestral 1840 audio/OBRA-020_capa.wav --semilla 632595 --raiz 528 && python3 03-composicion/ambiente.py audio/OBRA-020_528_shin.wav audio/OBRA-020_final.wav --fondo fuego --nivel-capa 0 --nivel-obra -20 --capa audio/OBRA-020_capa.wav | V21: publicada | W21: 2026-09-24 | Z21: =IFERROR(Y21/X21*1000,"")
A22: OBRA-021 | B22: Meditation Music · Zen Temple · 396 Hz · Bronze and Wood · 45 Minutes | C22: Música para meditar · Templo zen · 396 Hz · Bronce y madera · 45 minutos | D22: Meditar | E22: zen | F22: Bronze and Wood · 45 Minutes To accompany a meditation practice. Ambience: zen temple. Composed around a root of 396 Hz, in just intonation, kumoi mode. Breathing cycle: from 5.5 down to 4.5 breaths per minute, 40 % inhale / 60 % exhale. Original composition, synthesized from scratch, ambience included. No third-party samples. Best at low volume. Subscribe for new pieces: https://www.youtube.com/@rinchanneloficial?sub_confirmation=1 #meditationmusic #meditation #396hz | G22: Bronce y madera · 45 minutos Para acompañar una práctica de meditación. Ambiente: templo zen. Compuesta con raíz en 396 Hz, en entonación justa, modo kumoi. Ciclo respiratorio: de 5.5 a 4.5 respiraciones por minuto, inhalar 40 % / exhalar 60 %. Composición original, sintetizada desde cero: el ambiente también. Ninguna muestra procede de terceros. Mejor a volumen bajo. Suscríbete para las próximas obras: https://www.youtube.com/@rinchanneloficial?sub_confirmation=1 #meditationmusic #meditation #396hz | H22: 45 MIN | I22: #meditationmusic #meditation #396hz | J22: meditation music, 396 hz, 396 hz music, mindfulness, zen music, yoga music, zen temple, temple bells, wind chimes, relaxing music, calming music, ambient music, just intonation, original composition, Rin, música para meditar | M22: 396 | N22: kumoi | O22: medio | P22: 864630 | Q22: 70 | R22: 45 | S22: 0 | T22: python3 03-composicion/compositor.py --minutos 45 --raiz 396 --modo kumoi --semilla 864630 --caracter sin-cuenco | U22: python3 03-composicion/capas.py zen 2740 audio/OBRA-021_capa.wav --semilla 864630 --raiz 396 --densidad 1.4 && python3 03-composicion/ambiente.py audio/OBRA-021_396_kumoi.wav audio/OBRA-021_final.wav --fondo mar --nivel-fondo -7 --nivel-capa 2 --capa audio/OBRA-021_capa.wav | V22: pendiente | Z22: =IFERROR(Y22/X22*1000,"")
A23: OBRA-022 | B23: Meditation Music · Zen Temple · 639 Hz · Long Resonance · 1 Hour | C23: Música para meditar · Templo zen · 639 Hz · Resonancia larga · 1 hora | D23: Meditar | E23: zen | F23: Long Resonance · 1 Hour To accompany a meditation practice. Ambience: zen temple. Composed around a root of 639 Hz, in just intonation, yo mode. Breathing cycle: from 5.5 down to 4.5 breaths per minute, 40 % inhale / 60 % exhale. Original composition, synthesized from scratch, ambience included. No third-party samples. Best at low volume. Subscribe for new pieces: https://www.youtube.com/@rinchanneloficial?sub_confirmation=1 #meditationmusic #meditation #639hz | G23: Resonancia larga · 1 hora Para acompañar una práctica de meditación. Ambiente: templo zen. Compuesta con raíz en 639 Hz, en entonación justa, modo yo. Ciclo respiratorio: de 5.5 a 4.5 respiraciones por minuto, inhalar 40 % / exhalar 60 %. Composición original, sintetizada desde cero: el ambiente también. Ninguna muestra procede de terceros. Mejor a volumen bajo. Suscríbete para las próximas obras: https://www.youtube.com/@rinchanneloficial?sub_confirmation=1 #meditationmusic #meditation #639hz | H23: 60 MIN | I23: #meditationmusic #meditation #639hz | J23: meditation music, 639 hz, 639 hz music, mindfulness, zen music, yoga music, zen temple, temple bells, wind chimes, relaxing music, calming music, ambient music, just intonation, original composition, Rin, música para meditar | M23: 639 | N23: yo | O23: medio | P23: 335798 | Q23: 150 | R23: 60 | S23: 0 | T23: python3 03-composicion/compositor.py --minutos 60 --raiz 639 --modo yo --semilla 335798 --caracter sin-cuenco | U23: python3 03-composicion/capas.py zen 3640 audio/OBRA-022_capa.wav --semilla 335798 --raiz 639 --densidad 1.4 && python3 03-composicion/ambiente.py audio/OBRA-022_639_yo.wav audio/OBRA-022_final.wav --fondo mar --nivel-fondo -7 --nivel-capa 2 --capa audio/OBRA-022_capa.wav | V23: pendiente | Z23: =IFERROR(Y23/X23*1000,"")
A24: OBRA-023 | B24: Meditation Music · Zen Temple · 528 Hz · Just One · 20 Minutes | C24: Música para meditar · Templo zen · 528 Hz · Uno solo · 20 minutos | D24: Meditar | E24: zen | F24: Just One · 20 Minutes To accompany a meditation practice. Ambience: zen temple. Composed around a root of 528 Hz, in just intonation, shin mode. Breathing cycle: from 5.5 down to 4.5 breaths per minute, 40 % inhale / 60 % exhale. Original composition, synthesized from scratch, ambience included. No third-party samples. Best at low volume. Subscribe for new pieces: https://www.youtube.com/@rinchanneloficial?sub_confirmation=1 #meditationmusic #meditation #528hz | G24: Uno solo · 20 minutos Para acompañar una práctica de meditación. Ambiente: templo zen. Compuesta con raíz en 528 Hz, en entonación justa, modo shin. Ciclo respiratorio: de 5.5 a 4.5 respiraciones por minuto, inhalar 40 % / exhalar 60 %. Composición original, sintetizada desde cero: el ambiente también. Ninguna muestra procede de terceros. Mejor a volumen bajo. Suscríbete para las próximas obras: https://www.youtube.com/@rinchanneloficial?sub_confirmation=1 #meditationmusic #meditation #528hz | H24: 20 MIN | I24: #meditationmusic #meditation #528hz | J24: meditation music, 528 hz, 528 hz music, mindfulness, zen music, yoga music, zen temple, temple bells, wind chimes, relaxing music, calming music, ambient music, just intonation, original composition, Rin, música para meditar | M24: 528 | N24: shin | O24: medio | P24: 299306 | Q24: -35 | R24: 20 | S24: 0 | T24: python3 03-composicion/compositor.py --minutos 20 --raiz 528 --modo shin --semilla 299306 --caracter sin-cuenco | U24: python3 03-composicion/capas.py zen 1240 audio/OBRA-023_capa.wav --semilla 299306 --raiz 528 --densidad 1.4 && python3 03-composicion/ambiente.py audio/OBRA-023_528_shin.wav audio/OBRA-023_final.wav --fondo mar --nivel-fondo -7 --nivel-capa 2 --capa audio/OBRA-023_capa.wav | V24: pendiente | Z24: =IFERROR(Y24/X24*1000,"")
A25: OBRA-024 | B25: Meditation Music · Rain on Leaves · 432 Hz · What Remains of Sound · 1 Hour | C25: Música para meditar · Lluvia sobre hojas · 432 Hz · Lo que queda del sonido · 1 hora | D25: Meditar | E25: lluvia-tambor | F25: What Remains of Sound · 1 Hour To accompany a meditation practice. Ambience: rain on leaves. Composed around a root of 432 Hz, in just intonation, kumoi mode. Breathing cycle: from 5.5 down to 4.5 breaths per minute, 40 % inhale / 60 % exhale. Original composition, synthesized from scratch, ambience included. No third-party samples. Best at low volume. Subscribe for new pieces: https://www.youtube.com/@rinchanneloficial?sub_confirmation=1 #meditationmusic #meditation #432hz | G25: Lo que queda del sonido · 1 hora Para acompañar una práctica de meditación. Ambiente: lluvia sobre hojas. Compuesta con raíz en 432 Hz, en entonación justa, modo kumoi. Ciclo respiratorio: de 5.5 a 4.5 respiraciones por minuto, inhalar 40 % / exhalar 60 %. Composición original, sintetizada desde cero: el ambiente también. Ninguna muestra procede de terceros. Mejor a volumen bajo. Suscríbete para las próximas obras: https://www.youtube.com/@rinchanneloficial?sub_confirmation=1 #meditationmusic #meditation #432hz | H25: 60 MIN | I25: #meditationmusic #meditation #432hz | J25: meditation music, 432 hz, 432 hz music, mindfulness, zen music, yoga music, rain sounds, rain on leaves, shamanic drum, relaxing music, calming music, ambient music, just intonation, original composition, Rin, música para meditar | M25: 432 | N25: kumoi | O25: medio | P25: 926202 | Q25: -70 | R25: 60 | S25: 0 | T25: python3 03-composicion/compositor.py --minutos 60 --raiz 432 --modo kumoi --semilla 926202 --caracter sin-cuenco | U25: python3 03-composicion/capas.py ancestral 3640 audio/OBRA-024_capa.wav --semilla 926202 --raiz 432 && python3 03-composicion/ambiente.py audio/OBRA-024_432_kumoi.wav audio/OBRA-024_final.wav --fondo fuego --nivel-capa 0 --nivel-obra -20 --capa audio/OBRA-024_capa.wav | V25: pendiente | Z25: =IFERROR(Y25/X25*1000,"")
A26: OBRA-025 | B26: Music to Release Tension · Ocean and Birds · 528 Hz · Salt Root · 1 Hour | C26: Música para soltar tensión · Mar y pájaros · 528 Hz · Raíz de sal · 1 hora | D26: Soltar | E26: mar-aves | F26: Salt Root · 1 Hour To accompany some time to let go of the day's tension. Ambience: ocean and birds. Composed around a root of 528 Hz, in just intonation, hirajoshi mode. Breathing cycle: from 6.0 down to 4.5 breaths per minute, 40 % inhale / 60 % exhale. Original composition, synthesized from scratch, ambience included. No third-party samples. Best at low volume. Subscribe for new pieces: https://www.youtube.com/@rinchanneloficial?sub_confirmation=1 #relaxingmusic #meditation #528hz | G26: Raíz de sal · 1 hora Para acompañar un rato de soltar la tensión del día. Ambiente: mar y pájaros. Compuesta con raíz en 528 Hz, en entonación justa, modo hirajoshi. Ciclo respiratorio: de 6.0 a 4.5 respiraciones por minuto, inhalar 40 % / exhalar 60 %. Composición original, sintetizada desde cero: el ambiente también. Ninguna muestra procede de terceros. Mejor a volumen bajo. Suscríbete para las próximas obras: https://www.youtube.com/@rinchanneloficial?sub_confirmation=1 #relaxingmusic #meditation #528hz | H26: 528 HZ | I26: #relaxingmusic #meditation #528hz | J26: music to release tension, 528 hz, 528 hz music, stress relief, let go, healing music, ocean waves, birdsong, nature sounds, relaxing music, meditation music, calming music, ambient music, just intonation, original composition, Rin, música para soltar tensión | M26: 528 | N26: hirajoshi | O26: medio | P26: 454078 | Q26: 35 | R26: 60 | S26: 0 | T26: python3 03-composicion/compositor.py --minutos 60 --raiz 528 --modo hirajoshi --semilla 454078 --caracter sin-cuenco | U26: python3 03-composicion/capas.py aves 3640 audio/OBRA-025_capa.wav --semilla 454078 --raiz 528 && python3 03-composicion/ambiente.py audio/OBRA-025_528_hirajoshi.wav audio/OBRA-025_final.wav --fondo mar --nivel-capa -4 --capa audio/OBRA-025_capa.wav | V26: pendiente | Z26: =IFERROR(Y26/X26*1000,"")
A27: OBRA-026 | B27: Music to Release Tension · Ocean Waves · 432 Hz · Still Water · 1 Hour | C27: Música para soltar tensión · Olas del mar · 432 Hz · Agua quieta · 1 hora | D27: Soltar | E27: mar | F27: Still Water · 1 Hour To accompany some time to let go of the day's tension. Ambience: ocean waves. Composed around a root of 432 Hz, in just intonation, kumoi mode. Breathing cycle: from 6.0 down to 4.5 breaths per minute, 40 % inhale / 60 % exhale. Original composition, synthesized from scratch, ambience included. No third-party samples. Best at low volume. Subscribe for new pieces: https://www.youtube.com/@rinchanneloficial?sub_confirmation=1 #relaxingmusic #meditation #432hz | G27: Agua quieta · 1 hora Para acompañar un rato de soltar la tensión del día. Ambiente: olas del mar. Compuesta con raíz en 432 Hz, en entonación justa, modo kumoi. Ciclo respiratorio: de 6.0 a 4.5 respiraciones por minuto, inhalar 40 % / exhalar 60 %. Composición original, sintetizada desde cero: el ambiente también. Ninguna muestra procede de terceros. Mejor a volumen bajo. Suscríbete para las próximas obras: https://www.youtube.com/@rinchanneloficial?sub_confirmation=1 #relaxingmusic #meditation #432hz | H27: 432 HZ | I27: #relaxingmusic #meditation #432hz | J27: music to release tension, 432 hz, 432 hz music, stress relief, let go, healing music, ocean waves, sea sounds, relaxing music, meditation music, calming music, ambient music, just intonation, original composition, Rin, música para soltar tensión | M27: 432 | N27: kumoi | O27: medio | P27: 146597 | Q27: -35 | R27: 60 | S27: 0 | T27: python3 03-composicion/compositor.py --minutos 60 --raiz 432 --modo kumoi --semilla 146597 --caracter sin-cuenco | U27: python3 03-composicion/ambiente.py audio/OBRA-026_432_kumoi.wav audio/OBRA-026_final.wav --fondo mar | V27: pendiente | Z27: =IFERROR(Y27/X27*1000,"")
A28: OBRA-027 | B28: Music to Release Tension · Rain on Leaves · 396 Hz · Warm Ash · 1 Hour | C28: Música para soltar tensión · Lluvia sobre hojas · 396 Hz · Ceniza tibia · 1 hora | D28: Soltar | E28: lluvia-tambor | F28: Warm Ash · 1 Hour To accompany some time to let go of the day's tension. Ambience: rain on leaves. Composed around a root of 396 Hz, in just intonation, kumoi mode. Breathing cycle: from 6.0 down to 4.5 breaths per minute, 40 % inhale / 60 % exhale. Original composition, synthesized from scratch, ambience included. No third-party samples. Best at low volume. Subscribe for new pieces: https://www.youtube.com/@rinchanneloficial?sub_confirmation=1 #relaxingmusic #meditation #396hz | G28: Ceniza tibia · 1 hora Para acompañar un rato de soltar la tensión del día. Ambiente: lluvia sobre hojas. Compuesta con raíz en 396 Hz, en entonación justa, modo kumoi. Ciclo respiratorio: de 6.0 a 4.5 respiraciones por minuto, inhalar 40 % / exhalar 60 %. Composición original, sintetizada desde cero: el ambiente también. Ninguna muestra procede de terceros. Mejor a volumen bajo. Suscríbete para las próximas obras: https://www.youtube.com/@rinchanneloficial?sub_confirmation=1 #relaxingmusic #meditation #396hz | H28: 396 HZ | I28: #relaxingmusic #meditation #396hz | J28: music to release tension, 396 hz, 396 hz music, stress relief, let go, healing music, rain sounds, rain on leaves, shamanic drum, relaxing music, meditation music, calming music, ambient music, just intonation, original composition, Rin, música para soltar tensión | M28: 396 | N28: kumoi | O28: medio | P28: 338018 | Q28: 180 | R28: 60 | S28: 0 | T28: python3 03-composicion/compositor.py --minutos 60 --raiz 396 --modo kumoi --semilla 338018 --caracter sin-cuenco | U28: python3 03-composicion/capas.py ancestral 3640 audio/OBRA-027_capa.wav --semilla 338018 --raiz 396 && python3 03-composicion/ambiente.py audio/OBRA-027_396_kumoi.wav audio/OBRA-027_final.wav --fondo fuego --nivel-capa 0 --nivel-obra -20 --capa audio/OBRA-027_capa.wav | V28: pendiente | Z28: =IFERROR(Y28/X28*1000,"")
A29: OBRA-028 | B29: Music to Release Tension · Zen Temple · 417 Hz · Low Door · 45 Minutes | C29: Música para soltar tensión · Templo zen · 417 Hz · Puerta baja · 45 minutos | D29: Soltar | E29: zen | F29: Low Door · 45 Minutes To accompany some time to let go of the day's tension. Ambience: zen temple. Composed around a root of 417 Hz, in just intonation, hirajoshi mode. Breathing cycle: from 6.0 down to 4.5 breaths per minute, 40 % inhale / 60 % exhale. Original composition, synthesized from scratch, ambience included. No third-party samples. Best at low volume. Subscribe for new pieces: https://www.youtube.com/@rinchanneloficial?sub_confirmation=1 #relaxingmusic #meditation #417hz | G29: Puerta baja · 45 minutos Para acompañar un rato de soltar la tensión del día. Ambiente: templo zen. Compuesta con raíz en 417 Hz, en entonación justa, modo hirajoshi. Ciclo respiratorio: de 6.0 a 4.5 respiraciones por minuto, inhalar 40 % / exhalar 60 %. Composición original, sintetizada desde cero: el ambiente también. Ninguna muestra procede de terceros. Mejor a volumen bajo. Suscríbete para las próximas obras: https://www.youtube.com/@rinchanneloficial?sub_confirmation=1 #relaxingmusic #meditation #417hz | H29: 417 HZ | I29: #relaxingmusic #meditation #417hz | J29: music to release tension, 417 hz, 417 hz music, stress relief, let go, healing music, zen temple, temple bells, wind chimes, relaxing music, meditation music, calming music, ambient music, just intonation, original composition, Rin, música para soltar tensión | M29: 417 | N29: hirajoshi | O29: medio | P29: 409966 | Q29: -150 | R29: 45 | S29: 0 | T29: python3 03-composicion/compositor.py --minutos 45 --raiz 417 --modo hirajoshi --semilla 409966 --caracter sin-cuenco | U29: python3 03-composicion/capas.py zen 2740 audio/OBRA-028_capa.wav --semilla 409966 --raiz 417 --densidad 1.4 && python3 03-composicion/ambiente.py audio/OBRA-028_417_hirajoshi.wav audio/OBRA-028_final.wav --fondo mar --nivel-fondo -7 --nivel-capa 2 --capa audio/OBRA-028_capa.wav | V29: pendiente | Z29: =IFERROR(Y29/X29*1000,"")
A30: OBRA-029 | B30: Music to Release Tension · Tropical Rainforest · 639 Hz · Open Field · 1 Hour | C30: Música para soltar tensión · Selva tropical · 639 Hz · Campo abierto · 1 hora | D30: Soltar | E30: selva | F30: Open Field · 1 Hour To accompany some time to let go of the day's tension. Ambience: tropical rainforest. Composed around a root of 639 Hz, in just intonation, yo mode. Breathing cycle: from 6.0 down to 4.5 breaths per minute, 40 % inhale / 60 % exhale. Original composition, synthesized from scratch, ambience included. No third-party samples. Best at low volume. Subscribe for new pieces: https://www.youtube.com/@rinchanneloficial?sub_confirmation=1 #relaxingmusic #meditation #639hz | G30: Campo abierto · 1 hora Para acompañar un rato de soltar la tensión del día. Ambiente: selva tropical. Compuesta con raíz en 639 Hz, en entonación justa, modo yo. Ciclo respiratorio: de 6.0 a 4.5 respiraciones por minuto, inhalar 40 % / exhalar 60 %. Composición original, sintetizada desde cero: el ambiente también. Ninguna muestra procede de terceros. Mejor a volumen bajo. Suscríbete para las próximas obras: https://www.youtube.com/@rinchanneloficial?sub_confirmation=1 #relaxingmusic #meditation #639hz | H30: 639 HZ | I30: #relaxingmusic #meditation #639hz | J30: music to release tension, 639 hz, 639 hz music, stress relief, let go, healing music, rainforest sounds, birdsong, nature sounds, relaxing music, meditation music, calming music, ambient music, just intonation, original composition, Rin, música para soltar tensión | M30: 639 | N30: yo | O30: medio | P30: 133046 | Q30: 0 | R30: 60 | S30: 0 | T30: python3 03-composicion/compositor.py --minutos 60 --raiz 639 --modo yo --semilla 133046 --caracter sin-cuenco | U30: python3 03-composicion/capas.py aves 3640 audio/OBRA-029_capa.wav --semilla 133046 --raiz 639 --densidad 2 && python3 03-composicion/ambiente.py audio/OBRA-029_639_yo.wav audio/OBRA-029_final.wav --fondo selva --nivel-capa -2 --capa audio/OBRA-029_capa.wav | V30: pendiente | Z30: =IFERROR(Y30/X30*1000,"")
A31: OBRA-030 | B31: Music to Release Tension · Ocean and Birds · 741 Hz · Thin Air · 45 Minutes | C31: Música para soltar tensión · Mar y pájaros · 741 Hz · Aire delgado · 45 minutos | D31: Soltar | E31: mar-aves | F31: Thin Air · 45 Minutes To accompany some time to let go of the day's tension. Ambience: ocean and birds. Composed around a root of 741 Hz, in just intonation, yo mode. Breathing cycle: from 6.0 down to 4.5 breaths per minute, 40 % inhale / 60 % exhale. Original composition, synthesized from scratch, ambience included. No third-party samples. Best at low volume. Subscribe for new pieces: https://www.youtube.com/@rinchanneloficial?sub_confirmation=1 #relaxingmusic #meditation #741hz | G31: Aire delgado · 45 minutos Para acompañar un rato de soltar la tensión del día. Ambiente: mar y pájaros. Compuesta con raíz en 741 Hz, en entonación justa, modo yo. Ciclo respiratorio: de 6.0 a 4.5 respiraciones por minuto, inhalar 40 % / exhalar 60 %. Composición original, sintetizada desde cero: el ambiente también. Ninguna muestra procede de terceros. Mejor a volumen bajo. Suscríbete para las próximas obras: https://www.youtube.com/@rinchanneloficial?sub_confirmation=1 #relaxingmusic #meditation #741hz | H31: 741 HZ | I31: #relaxingmusic #meditation #741hz | J31: music to release tension, 741 hz, 741 hz music, stress relief, let go, healing music, ocean waves, birdsong, nature sounds, relaxing music, meditation music, calming music, ambient music, just intonation, original composition, Rin, música para soltar tensión | M31: 741 | N31: yo | O31: medio | P31: 244487 | Q31: -110 | R31: 45 | S31: 0 | T31: python3 03-composicion/compositor.py --minutos 45 --raiz 741 --modo yo --semilla 244487 --caracter sin-cuenco | U31: python3 03-composicion/capas.py aves 2740 audio/OBRA-030_capa.wav --semilla 244487 --raiz 741 && python3 03-composicion/ambiente.py audio/OBRA-030_741_yo.wav audio/OBRA-030_final.wav --fondo mar --nivel-capa -4 --capa audio/OBRA-030_capa.wav | V31: pendiente | Z31: =IFERROR(Y31/X31*1000,"")
